<?xml version="1.0" encoding="UTF-8"?>
<testng-results skipped="0" failed="1" total="1" passed="0">
  <reporter-output>
  </reporter-output>
  <suite name="Default suite" duration-ms="52931" started-at="2018-08-21T11:07:42Z" finished-at="2018-08-21T11:08:35Z">
    <groups>
    </groups>
    <test name="Default test" duration-ms="52931" started-at="2018-08-21T11:07:42Z" finished-at="2018-08-21T11:08:35Z">
      <class name="demopackage.TC001_Login">
        <test-method status="PASS" signature="setProcess()[pri:0, instance:demopackage.TC001_Login@6d8a00e3]" name="setProcess" is-config="true" duration-ms="47796" started-at="2018-08-21T16:37:42Z" finished-at="2018-08-21T16:38:30Z">
          <reporter-output>
          </reporter-output>
        </test-method> <!-- setProcess -->
        <test-method status="FAIL" signature="login()[pri:0, instance:demopackage.TC001_Login@6d8a00e3]" name="login" duration-ms="4895" started-at="2018-08-21T16:38:30Z" finished-at="2018-08-21T16:38:35Z">
          <exception class="java.lang.AssertionError">
            <message>
              <![CDATA[expected [Authentication failed.] but found [Authentication failed]]]>
            </message>
            <full-stacktrace>
              <![CDATA[java.lang.AssertionError: expected [Authentication failed.] but found [Authentication failed]
	at org.testng.Assert.fail(Assert.java:94)
	at org.testng.Assert.failNotEquals(Assert.java:513)
	at org.testng.Assert.assertEqualsImpl(Assert.java:135)
	at org.testng.Assert.assertEquals(Assert.java:116)
	at org.testng.Assert.assertEquals(Assert.java:190)
	at org.testng.Assert.assertEquals(Assert.java:200)
	at demopackage.TC001_Login.login(TC001_Login.java:26)
	at sun.reflect.NativeMethodAccessorImpl.invoke0(Native Method)
	at sun.reflect.NativeMethodAccessorImpl.invoke(NativeMethodAccessorImpl.java:62)
	at sun.reflect.DelegatingMethodAccessorImpl.invoke(DelegatingMethodAccessorImpl.java:43)
	at java.lang.reflect.Method.invoke(Method.java:498)
	at org.testng.internal.MethodInvocationHelper.invokeMethod(MethodInvocationHelper.java:86)
	at org.testng.internal.Invoker.invokeMethod(Invoker.java:646)
	at org.testng.internal.Invoker.invokeTestMethod(Invoker.java:823)
	at org.testng.internal.Invoker.invokeTestMethods(Invoker.java:1131)
	at org.testng.internal.TestMethodWorker.invokeTestMethods(TestMethodWorker.java:129)
	at org.testng.internal.TestMethodWorker.run(TestMethodWorker.java:112)
	at org.testng.TestRunner.privateRun(TestRunner.java:778)
	at org.testng.TestRunner.run(TestRunner.java:632)
	at org.testng.SuiteRunner.runTest(SuiteRunner.java:366)
	at org.testng.SuiteRunner.runSequentially(SuiteRunner.java:361)
	at org.testng.SuiteRunner.privateRun(SuiteRunner.java:319)
	at org.testng.SuiteRunner.run(SuiteRunner.java:268)
	at org.testng.SuiteRunnerWorker.runSuite(SuiteRunnerWorker.java:52)
	at org.testng.SuiteRunnerWorker.run(SuiteRunnerWorker.java:86)
	at org.testng.TestNG.runSuitesSequentially(TestNG.java:1225)
	at org.testng.TestNG.runSuitesLocally(TestNG.java:1150)
	at org.testng.TestNG.runSuites(TestNG.java:1075)
	at org.testng.TestNG.run(TestNG.java:1047)
	at org.testng.remote.AbstractRemoteTestNG.run(AbstractRemoteTestNG.java:126)
	at org.testng.remote.RemoteTestNG.initAndRun(RemoteTestNG.java:137)
	at org.testng.remote.RemoteTestNG.main(RemoteTestNG.java:58)
]]>
            </full-stacktrace>
          </exception> <!-- java.lang.AssertionError -->
          <reporter-output>
          </reporter-output>
        </test-method> <!-- login -->
        <test-method status="PASS" signature="endProcess()[pri:0, instance:demopackage.TC001_Login@6d8a00e3]" name="endProcess" is-config="true" duration-ms="0" started-at="2018-08-21T16:38:35Z" finished-at="2018-08-21T16:38:35Z">
          <reporter-output>
          </reporter-output>
        </test-method> <!-- endProcess -->
      </class> <!-- demopackage.TC001_Login -->
    </test> <!-- Default test -->
  </suite> <!-- Default suite -->
</testng-results>
